Workbook
Name Bancos: OFFSET(#REF!,0,0,COUNTA(#REF!)-1)
Name FromOrganiz_1: _xlfn.ANCHORARRAY('Para Inf Web'!$A$5)
Name SegmentaciónDeDatos_Año: #N/A
Name SegmentaciónDeDatos_CtaCtbl: #N/A
Name SegmentaciónDeDatos_CtaCtbl2: #N/A
Name SegmentaciónDeDatos_Descripción: #N/A
Name SegmentaciónDeDatos_Mes: #N/A
Name UF: #REF!

Sheet Top 5
A1: Top 5 - Ingresos | D1: Top 5 - Egresos
A2: Año | B2: 2025 | D2: Año | E2: 2025
A3: Mes | B3: Noviembre | D3: Mes | E3: Noviembre
A5: Etiquetas de fila | D5: Etiquetas de fila | E5: Cargos
A6: Cuota Ordinaria | D6: Cuota Ordinaria | E6: 0
A7: Pago Comisiones | D7: Pago Comisiones | E7: 23569
A8: Sitio corporativo web | D8: Sitio corporativo web | E8: 207152
A9: Taxi, Uber o Similar | D9: Taxi, Uber o Similar | E9: 6294
A10: Total general | D10: Total general | E10: 237015

Sheet Para Inf Web
A1: Año | B1: 2025 | D1: =UPPER("Finanzas "&B2&" del "&B1) -> FINANZAS DICIEMBRE DEL 2025
A2: Mes | B2: Diciembre | D2: =UPPER("Distribución de los Egresos a "&B2&" del "&B1) -> DISTRIBUCIÓN DE LOS EGRESOS A DICIEMBRE DEL 2025 | G2: Saldo | I2: =G3+I3 -> 17877600
G3: =SUBTOTAL(9,G5:G1000) -> 17877600 | H3: =SUBTOTAL(9,H5:H1000) -> 0 | I3: =SUBTOTAL(9,I5:I1000) -> 0
A5: {=_xlfn.LET( _xlpm.Filtrados, _xlfn.LET( _xlpm.datos,_xlfn.CHOOSECOLS(Banco[],1,2,8,9,13), _xlfn._xlws.FILTER(_xlpm.datos,(_xlfn.CHOOSECOLS(_xlpm.datos,1)=B1)*(_xlfn.CHOOSECOLS(_xlpm.datos,2)=B2),"Sin Datos") ), _xlfn.GROUPBY( _xlpm.Filtrados,_xlfn.CHOOSECOLS(_xlpm.Filtrados,3,4),_xleta.SUM ) )} -> 2025 | B5: Diciembre | C5: 0 | D5: 8938800 | E5: Cuota Ordinaria | F5: 0 | G5: 8938800
A6: 2025 | B6: Diciembre | C6: 23588 | D6: 0 | E6: Pago Comisiones | F6: 23588 | G6: 0
A7: 2025 | B7: Diciembre | C7: 39500 | D7: 0 | E7: Coronas de Caridad Condolencias | F7: 39500 | G7: 0
A8: 2025 | B8: Diciembre | C8: 350000 | D8: 0 | E8: Asesoria Legal - Convenio Fijo Mensual | F8: 1400000 | G8: 0
A9: 2025 | B9: Diciembre | C9: 500000 | D9: 0 | E9: Regalo Corportivo (Aniversario) | F9: 500000 | G9: 0
A10: 2025 | B10: Diciembre | C10: 1457600 | D10: 0 | E10: Regalo Corportivo (Aniversario) | F10: 1457600 | G10: 0
A11: 2025 | B11: Diciembre | C11: 5000000 | D11: 0 | E11: Regalo Corportivo (Aniversario) | F11: 15000000 | G11: 0
A12: Total | F12: 18420688 | G12: 8938800
B32: {=_xludf.UNIQUE(_xlfn._xlws.FILTER(Banco[Nombre Cuenta],(Banco[Año]=B1)*(Banco[Mes]=B2)))} -> #NAME?

Sheet Hoja1
T1: Año | U1: Mes
T2: 2021 | U2: Enero
T3: 2022 | U3: Febrero
T4: 2023 | U4: Marzo
T5: 2024 | U5: Abril
T6: 2025 | U6: Mayo
T7: 2026 | U7: Junio
U8: Julio
U9: Agosto
U10: Septiembre
U11: Octubre
U12: Noviembre
U13: Diciembre

Sheet Banco
G9: Saldo | I9: =I11+G11 -> 8361633
F11: =SUBTOTAL(9,F231:F10064) -> 0 | G11: =SUBTOTAL(9,G13:G1028) -> -18824299 | I11: =SUBTOTAL(9,I13:I1028) -> 27185932 | J11: =SUBTOTAL(9,J13:J10064) -> 0 | K11: =SUBTOTAL(9,(K12:K1028)) -> 8361633
A12: Año | B12: Mes | C12: Periodo Contable | D12: Fecha | E12: Descripción | F12: N° Doc. | G12: cargos | H12: Egresos | I12: Ingresos | J12: Saldo | K12: Monto | L12: CtaCtbl | M12: Nombre Cuenta | N12: Observacion del Gasto o Abono / Link a Document0o Respaldo | O12: Cartola
A13: =YEAR(Banco[[#This Row],[Fecha]]) -> 2021 | B13: =PROPER(TEXT(Banco[[#This Row],[Fecha]],"MMMM")) -> Septiembre | C13: =TEXT(Banco[[#This Row],[Fecha]],"mmm-yyyy") -> sept-2021 | D13: 44440 | E13: APERTURA CUENTA CORRIENTE | F13: ------- | G13: 0 | H13: =Banco[[#This Row],[cargos]]*-1 -> 0 | I13: 0 | J13: 0 | K13: =+Banco[[#This Row],[cargos]]+Banco[[#This Row],[Ingresos]] -> 0 | L13: 3.03.03 - Otros Pagos | M13: =MID(Banco[[#This Row],[CtaCtbl]],FIND(" - ",Banco[[#This Row],[CtaCtbl]])+3,40) -> Otros Pagos
A14: =YEAR(Banco[[#This Row],[Fecha]]) -> 2021 | B14: =PROPER(TEXT(Banco[[#This Row],[Fecha]],"MMMM")) -> Octubre | C14: =TEXT(Banco[[#This Row],[Fecha]],"mmm-yyyy") -> oct-2021 | D14: 44496 | E14: PROVEEDORE 96505760-9 COLBUN M | G14: 0 | H14: =Banco[[#This Row],[cargos]]*-1 -> 0 | I14: 2349346 | K14: =+Banco[[#This Row],[cargos]]+Banco[[#This Row],[Ingresos]] -> 2349346 | L14: 1.01.02 - Cuota Extraordinaria | M14: =MID(Banco[[#This Row],[CtaCtbl]],FIND(" - ",Banco[[#This Row],[CtaCtbl]])+3,40) -> Cuota Extraordinaria
A15: =YEAR(Banco[[#This Row],[Fecha]]) -> 2021 | B15: =PROPER(TEXT(Banco[[#This Row],[Fecha]],"MMMM")) -> Octubre | C15: =TEXT(Banco[[#This Row],[Fecha]],"mmm-yyyy") -> oct-2021 | D15: 44496 | E15: PROVEEDORE 96505760-9 COLBUN M | G15: 0 | H15: =Banco[[#This Row],[cargos]]*-1 -> 0 | I15: 4445566 | J15: 6794912 | K15: =+Banco[[#This Row],[cargos]]+Banco[[#This Row],[Ingresos]] -> 4445566 | L15: 1.01.01 - Cuota Ordinaria | M15: =MID(Banco[[#This Row],[CtaCtbl]],FIND(" - ",Banco[[#This Row],[CtaCtbl]])+3,40) -> Cuota Ordinaria
A16: =YEAR(Banco[[#This Row],[Fecha]]) -> 2021 | B16: =PROPER(TEXT(Banco[[#This Row],[Fecha]],"MMMM")) -> Noviembre | C16: =TEXT(Banco[[#This Row],[Fecha]],"mmm-yyyy") -> nov-2021 | D16: 44509 | E16: TEF 14082906-4 Alejandra Saldi | G16: -234341 | H16: =Banco[[#This Row],[cargos]]*-1 -> 234341 | I16: 0 | J16: 6560571 | K16: =+Banco[[#This Row],[cargos]]+Banco[[#This Row],[Ingresos]] -> -234341 | L16: 2.01.03.03.1.9 - Traslado Terrestre Van/Taxi,etc | M16: =MID(Banco[[#This Row],[CtaCtbl]],FIND(" - ",Banco[[#This Row],[CtaCtbl]])+3,40) -> Traslado Terrestre Van/Taxi,etc
A17: =YEAR(Banco[[#This Row],[Fecha]]) -> 2021 | B17: =PROPER(TEXT(Banco[[#This Row],[Fecha]],"MMMM")) -> Noviembre | C17: =TEXT(Banco[[#This Row],[Fecha]],"mmm-yyyy") -> nov-2021 | D17: 44509 | E17: TEF 17412336-5 Robinson Cornej | G17: -380230 | H17: =Banco[[#This Row],[cargos]]*-1 -> 380230 | I17: 0 | J17: 6180341 | K17: =+Banco[[#This Row],[cargos]]+Banco[[#This Row],[Ingresos]] -> -380230 | L17: 2.01.03.03.1.9 - Traslado Terrestre Van/Taxi,etc | M17: =MID(Banco[[#This Row],[CtaCtbl]],FIND(" - ",Banco[[#This Row],[CtaCtbl]])+3,40) -> Traslado Terrestre Van/Taxi,etc
A18: =YEAR(Banco[[#This Row],[Fecha]]) -> 2021 | B18: =PROPER(TEXT(Banco[[#This Row],[Fecha]],"MMMM")) -> Noviembre | C18: =TEXT(Banco[[#This Row],[Fecha]],"mmm-yyyy") -> nov-2021 | D18: 44509 | E18: TEF 76194207-7 Estudio Juridic | G18: -108500 | H18: =Banco[[#This Row],[cargos]]*-1 -> 108500 | I18: 0 | J18: 6071841 | K18: =+Banco[[#This Row],[cargos]]+Banco[[#This Row],[Ingresos]] -> -108500 | L18: 2.01.01.01.1 - Asesoria Legal - Convenio Fijo Mensual | M18: =MID(Banco[[#This Row],[CtaCtbl]],FIND(" - ",Banco[[#This Row],[CtaCtbl]])+3,40) -> Asesoria Legal - Convenio Fijo Mensual
A19: =YEAR(Banco[[#This Row],[Fecha]]) -> 2021 | B19: =PROPER(TEXT(Banco[[#This Row],[Fecha]],"MMMM")) -> Noviembre | C19: =TEXT(Banco[[#This Row],[Fecha]],"mmm-yyyy") -> nov-2021 | D19: 44526 | E19: PROVEEDORE 96505760-9 COLBUN M | G19: 0 | H19: =Banco[[#This Row],[cargos]]*-1 -> 0 | I19: 107667 | K19: =+Banco[[#This Row],[cargos]]+Banco[[#This Row],[Ingresos]] -> 107667 | L19: 1.01.02 - Cuota Extraordinaria | M19: =MID(Banco[[#This Row],[CtaCtbl]],FIND(" - ",Banco[[#This Row],[CtaCtbl]])+3,40) -> Cuota Extraordinaria
A20: =YEAR(Banco[[#This Row],[Fecha]]) -> 2021 | B20: =PROPER(TEXT(Banco[[#This Row],[Fecha]],"MMMM")) -> Noviembre | C20: =TEXT(Banco[[#This Row],[Fecha]],"mmm-yyyy") -> nov-2021 | D20: 44526 | E20: PROVEEDORE 96505760-9 COLBUN M | G20: 0 | H20: =Banco[[#This Row],[cargos]]*-1 -> 0 | I20: 2476341 | J20: 8655849 | K20: =+Banco[[#This Row],[cargos]]+Banco[[#This Row],[Ingresos]] -> 2476341 | L20: 1.01.01 - Cuota Ordinaria | M20: =MID(Banco[[#This Row],[CtaCtbl]],FIND(" - ",Banco[[#This Row],[CtaCtbl]])+3,40) -> Cuota Ordinaria
A21: =YEAR(Banco[[#This Row],[Fecha]]) -> 2021 | B21: =PROPER(TEXT(Banco[[#This Row],[Fecha]],"MMMM")) -> Diciembre | C21: =TEXT(Banco[[#This Row],[Fecha]],"mmm-yyyy") -> dic-2021 | D21: 44531 | E21: COBRO COMISION SCOTIAWEB | G21: -18312 | H21: =Banco[[#This Row],[cargos]]*-1 -> 18312 | I21: 0 | J21: 8637537 | K21: =+Banco[[#This Row],[cargos]]+Banco[[#This Row],[Ingresos]] -> -18312 | L21: 3.03.01 - Pago Comisiones | M21: =MID(Banco[[#This Row],[CtaCtbl]],FIND(" - ",Banco[[#This Row],[CtaCtbl]])+3,40) -> Pago Comisiones
A22: =YEAR(Banco[[#This Row],[Fecha]]) -> 2021 | B22: =PROPER(TEXT(Banco[[#This Row],[Fecha]],"MMMM")) -> Diciembre | C22: =TEXT(Banco[[#This Row],[Fecha]],"mmm-yyyy") -> dic-2021 | D22: 44537 | E22: TEF 76194207-7 Estudio Juridic | G22: -113400 | H22: =Banco[[#This Row],[cargos]]*-1 -> 113400 | I22: 0 | J22: 8524137 | K22: =+Banco[[#This Row],[cargos]]+Banco[[#This Row],[Ingresos]] -> -113400 | L22: 2.01.01.01.1 - Asesoria Legal - Convenio Fijo Mensual | M22: =MID(Banco[[#This Row],[CtaCtbl]],FIND(" - ",Banco[[#This Row],[CtaCtbl]])+3,40) -> Asesoria Legal - Convenio Fijo Mensual
A23: =YEAR(Banco[[#This Row],[Fecha]]) -> 2021 | B23: =PROPER(TEXT(Banco[[#This Row],[Fecha]],"MMMM")) -> Diciembre | C23: =TEXT(Banco[[#This Row],[Fecha]],"mmm-yyyy") -> dic-2021 | D23: 44558 | E23: PROVEEDORE 96505760-9 COLBUN M | G23: 0 | H23: =Banco[[#This Row],[cargos]]*-1 -> 0 | I23: 216944 | K23: =+Banco[[#This Row],[cargos]]+Banco[[#This Row],[Ingresos]] -> 216944 | L23: 1.01.02 - Cuota Extraordinaria | M23: =MID(Banco[[#This Row],[CtaCtbl]],FIND(" - ",Banco[[#This Row],[CtaCtbl]])+3,40) -> Cuota Extraordinaria
A24: =YEAR(Banco[[#This Row],[Fecha]]) -> 2021 | B24: =PROPER(TEXT(Banco[[#This Row],[Fecha]],"MMMM")) -> Diciembre | C24: =TEXT(Banco[[#This Row],[Fecha]],"mmm-yyyy") -> dic-2021 | D24: 44558 | E24: PROVEEDORE 96505760-9 COLBUN M | G24: 0 | H24: =Banco[[#This Row],[cargos]]*-1 -> 0 | I24: 2665312 | J24: 11406393 | K24: =+Banco[[#This Row],[cargos]]+Banco[[#This Row],[Ingresos]] -> 2665312 | L24: 1.01.01 - Cuota Ordinaria | M24: =MID(Banco[[#This Row],[CtaCtbl]],FIND(" - ",Banco[[#This Row],[CtaCtbl]])+3,40) -> Cuota Ordinaria
A25: =YEAR(Banco[[#This Row],[Fecha]]) -> 2022 | B25: =PROPER(TEXT(Banco[[#This Row],[Fecha]],"MMMM")) -> Enero | C25: =TEXT(Banco[[#This Row],[Fecha]],"mmm-yyyy") -> ene-2022 | D25: 44564 | E25: COBRO COMISION SCOTIAWEB | G25: -18449 | H25: =Banco[[#This Row],[cargos]]*-1 -> 18449 | I25: 0 | J25: 11387944 | K25: =+Banco[[#This Row],[cargos]]+Banco[[#This Row],[Ingresos]] -> -18449 | L25: 3.03.01 - Pago Comisiones | M25: =MID(Banco[[#This Row],[CtaCtbl]],FIND(" - ",Banco[[#This Row],[CtaCtbl]])+3,40) -> Pago Comisiones
A26: =YEAR(Banco[[#This Row],[Fecha]]) -> 2022 | B26: =PROPER(TEXT(Banco[[#This Row],[Fecha]],"MMMM")) -> Enero | C26: =TEXT(Banco[[#This Row],[Fecha]],"mmm-yyyy") -> ene-2022 | D26: 44572 | E26: TEF 76194207-7 Estudio Juridic | G26: -121100 | H26: =Banco[[#This Row],[cargos]]*-1 -> 121100 | I26: 0 | J26: 11266844 | K26: =+Banco[[#This Row],[cargos]]+Banco[[#This Row],[Ingresos]] -> -121100 | L26: 2.01.01.01.1 - Asesoria Legal - Convenio Fijo Mensual | M26: =MID(Banco[[#This Row],[CtaCtbl]],FIND(" - ",Banco[[#This Row],[CtaCtbl]])+3,40) -> Asesoria Legal - Convenio Fijo Mensual | N26: EJ Mes Dic 2021 - Factura N° 0249
A27: 2022 | B27: Enero | C27: ene-2022 | D27: 44588 | E27: PROVEEDORE 96505760-9 COLBUN M | G27: 0 | H27: =Banco[[#This Row],[cargos]]*-1 -> 0 | I27: 109242 | J27: 2840292 | K27: =+Banco[[#This Row],[cargos]]+Banco[[#This Row],[Ingresos]] -> 109242 | L27: 1.01.02 - Cuota Extraordinaria | M27: =MID(Banco[[#This Row],[CtaCtbl]],FIND(" - ",Banco[[#This Row],[CtaCtbl]])+3,40) -> Cuota Extraordinaria
A28: 2022 | B28: Enero | C28: ene-2022 | D28: 44588 | E28: PROVEEDORE 96505760-9 COLBUN M | G28: 0 | H28: =Banco[[#This Row],[cargos]]*-1 -> 0 | I28: 2731050 | J28: 2840292 | K28: =+Banco[[#This Row],[cargos]]+Banco[[#This Row],[Ingresos]] -> 2731050 | L28: 1.01.01 - Cuota Ordinaria | M28: =MID(Banco[[#This Row],[CtaCtbl]],FIND(" - ",Banco[[#This Row],[CtaCtbl]])+3,40) -> Cuota Ordinaria
A29: =YEAR(Banco[[#This Row],[Fecha]]) -> 2022 | B29: =PROPER(TEXT(Banco[[#This Row],[Fecha]],"MMMM")) -> Enero | C29: =TEXT(Banco[[#This Row],[Fecha]],"mmm-yyyy") -> ene-2022 | D29: 44589 | E29: TEF 12379484-2 Abdel Karim Aza | G29: -34560 | H29: =Banco[[#This Row],[cargos]]*-1 -> 34560 | I29: 0 | J29: 13972576 | K29: =+Banco[[#This Row],[cargos]]+Banco[[#This Row],[Ingresos]] -> -34560 | L29: 2.01.04.01.2 - Almuerzo | M29: =MID(Banco[[#This Row],[CtaCtbl]],FIND(" - ",Banco[[#This Row],[CtaCtbl]])+3,40) -> Almuerzo
A30: =YEAR(Banco[[#This Row],[Fecha]]) -> 2022 | B30: =PROPER(TEXT(Banco[[#This Row],[Fecha]],"MMMM")) -> Enero | C30: =TEXT(Banco[[#This Row],[Fecha]],"mmm-yyyy") -> ene-2022 | D30: 44589 | E30: TEF 17412336-5 Robinson Cornej | G30: -233827 | H30: =Banco[[#This Row],[cargos]]*-1 -> 233827 | I30: 0 | J30: 13738749 | K30: =+Banco[[#This Row],[cargos]]+Banco[[#This Row],[Ingresos]] -> -233827 | L30: 2.01.03.03.1.9 - Traslado Terrestre Van/Taxi,etc | M30: =MID(Banco[[#This Row],[CtaCtbl]],FIND(" - ",Banco[[#This Row],[CtaCtbl]])+3,40) -> Traslado Terrestre Van/Taxi,etc
A31: =YEAR(Banco[[#This Row],[Fecha]]) -> 2022 | B31: =PROPER(TEXT(Banco[[#This Row],[Fecha]],"MMMM")) -> Enero | C31: =TEXT(Banco[[#This Row],[Fecha]],"mmm-yyyy") -> ene-2022 | D31: 44589 | E31: TEF 76197051-8 RED HOTELERA CH | G31: -100000 | H31: =Banco[[#This Row],[cargos]]*-1 -> 100000 | I31: 0 | J31: 14007136 | K31: =+Banco[[#This Row],[cargos]]+Banco[[#This Row],[Ingresos]] -> -100000 | L31: 2.01.04.02 - Alojamiento | M31: =MID(Banco[[#This Row],[CtaCtbl]],FIND(" - ",Banco[[#This Row],[CtaCtbl]])+3,40) -> Alojamiento
A32: =YEAR(Banco[[#This Row],[Fecha]]) -> 2022 | B32: =PROPER(TEXT(Banco[[#This Row],[Fecha]],"MMMM")) -> Enero | C32: =TEXT(Banco[[#This Row],[Fecha]],"mmm-yyyy") -> ene-2022 | D32: 44592 | E32: TEF 76016422-4 Hotel Avellano | G32: -65450 | H32: =Banco[[#This Row],[cargos]]*-1 -> 65450 | I32: 0 | J32: 13673299 | K32: =+Banco[[#This Row],[cargos]]+Banco[[#This Row],[Ingresos]] -> -65450 | L32: 2.01.04.02 - Alojamiento | M32: =MID(Banco[[#This Row],[CtaCtbl]],FIND(" - ",Banco[[#This Row],[CtaCtbl]])+3,40) -> Alojamiento
A33: =YEAR(Banco[[#This Row],[Fecha]]) -> 2022 | B33: =PROPER(TEXT(Banco[[#This Row],[Fecha]],"MMMM")) -> Febrero | C33: =TEXT(Banco[[#This Row],[Fecha]],"mmm-yyyy") -> feb-2022 | D33: 44593 | E33: COBRO COMISION SCOTIAWEB | G33: -18576 | H33: =Banco[[#This Row],[cargos]]*-1 -> 18576 | I33: 0 | J33: 13654723 | K33: =+Banco[[#This Row],[cargos]]+Banco[[#This Row],[Ingresos]] -> -18576 | L33: 3.03.01 - Pago Comisiones | M33: =MID(Banco[[#This Row],[CtaCtbl]],FIND(" - ",Banco[[#This Row],[CtaCtbl]])+3,40) -> Pago Comisiones
A34: =YEAR(Banco[[#This Row],[Fecha]]) -> 2022 | B34: =PROPER(TEXT(Banco[[#This Row],[Fecha]],"MMMM")) -> Febrero | C34: =TEXT(Banco[[#This Row],[Fecha]],"mmm-yyyy") -> feb-2022 | D34: 44602 | E34: TEF 12379484-2 Abdel Karim Aza | G34: -119949 | H34: =Banco[[#This Row],[cargos]]*-1 -> 119949 | I34: 0 | J34: 13446574 | K34: =+Banco[[#This Row],[cargos]]+Banco[[#This Row],[Ingresos]] -> -119949 | L34: 2.01.03.03.1.9 - Traslado Terrestre Van/Taxi,etc | M34: =MID(Banco[[#This Row],[CtaCtbl]],FIND(" - ",Banco[[#This Row],[CtaCtbl]])+3,40) -> Traslado Terrestre Van/Taxi,etc
A35: =YEAR(Banco[[#This Row],[Fecha]]) -> 2022 | B35: =PROPER(TEXT(Banco[[#This Row],[Fecha]],"MMMM")) -> Febrero | C35: =TEXT(Banco[[#This Row],[Fecha]],"mmm-yyyy") -> feb-2022 | D35: 44602 | E35: TEF 76194207-7 Estudio Juridic | G35: -88200 | H35: =Banco[[#This Row],[cargos]]*-1 -> 88200 | I35: 0 | J35: 13566523 | K35: =+Banco[[#This Row],[cargos]]+Banco[[#This Row],[Ingresos]] -> -88200 | L35: 2.01.01.01.1 - Asesoria Legal - Convenio Fijo Mensual | M35: =MID(Banco[[#This Row],[CtaCtbl]],FIND(" - ",Banco[[#This Row],[CtaCtbl]])+3,40) -> Asesoria Legal - Convenio Fijo Mensual | N35: EJ Mes Ene 2022 - Factura N°0250
A36: =YEAR(Banco[[#This Row],[Fecha]]) -> 2022 | B36: =PROPER(TEXT(Banco[[#This Row],[Fecha]],"MMMM")) -> Febrero | C36: =TEXT(Banco[[#This Row],[Fecha]],"mmm-yyyy") -> feb-2022 | D36: 44617 | E36: PROVEEDORE 96505760-9 COLBUN M | G36: 0 | H36: =Banco[[#This Row],[cargos]]*-1 -> 0 | I36: 282712 | K36: =+Banco[[#This Row],[cargos]]+Banco[[#This Row],[Ingresos]] -> 282712 | L36: 1.01.02 - Cuota Extraordinaria | M36: =MID(Banco[[#This Row],[CtaCtbl]],FIND(" - ",Banco[[#This Row],[CtaCtbl]])+3,40) -> Cuota Extraordinaria
A37: =YEAR(Banco[[#This Row],[Fecha]]) -> 2022 | B37: =PROPER(TEXT(Banco[[#This Row],[Fecha]],"MMMM")) -> Febrero | C37: =TEXT(Banco[[#This Row],[Fecha]],"mmm-yyyy") -> feb-2022 | D37: 44617 | E37: PROVEEDORE 96505760-9 COLBUN M | G37: 0 | H37: =Banco[[#This Row],[cargos]]*-1 -> 0 | I37: 2917450 | J37: 16646736 | K37: =+Banco[[#This Row],[cargos]]+Banco[[#This Row],[Ingresos]] -> 2917450 | L37: 1.01.01 - Cuota Ordinaria | M37: =MID(Banco[[#This Row],[CtaCtbl]],FIND(" - ",Banco[[#This Row],[CtaCtbl]])+3,40) -> Cuota Ordinaria
A38: =YEAR(Banco[[#This Row],[Fecha]]) -> 2022 | B38: =PROPER(TEXT(Banco[[#This Row],[Fecha]],"MMMM")) -> Marzo | C38: =TEXT(Banco[[#This Row],[Fecha]],"mmm-yyyy") -> mar-2022 | D38: 44621 | E38: COBRO COMISION SCOTIAWEB | G38: -18773 | H38: =Banco[[#This Row],[cargos]]*-1 -> 18773 | I38: 0 | J38: 16627963 | K38: =+Banco[[#This Row],[cargos]]+Banco[[#This Row],[Ingresos]] -> -18773 | L38: 3.03.01 - Pago Comisiones | M38: =MID(Banco[[#This Row],[CtaCtbl]],FIND(" - ",Banco[[#This Row],[CtaCtbl]])+3,40) -> Pago Comisiones
A39: =YEAR(Banco[[#This Row],[Fecha]]) -> 2022 | B39: =PROPER(TEXT(Banco[[#This Row],[Fecha]],"MMMM")) -> Marzo | C39: =TEXT(Banco[[#This Row],[Fecha]],"mmm-yyyy") -> mar-2022 | D39: 44628 | E39: TEF 12379484-2 Abdel Karim Aza | G39: -2300 | H39: =Banco[[#This Row],[cargos]]*-1 -> 2300 | I39: 0 | J39: 16609847 | K39: =+Banco[[#This Row],[cargos]]+Banco[[#This Row],[Ingresos]] -> -2300 | L39: 2.01.03.03.1.9 - Traslado Terrestre Van/Taxi,etc | M39: =MID(Banco[[#This Row],[CtaCtbl]],FIND(" - ",Banco[[#This Row],[CtaCtbl]])+3,40) -> Traslado Terrestre Van/Taxi,etc
A40: =YEAR(Banco[[#This Row],[Fecha]]) -> 2022 | B40: =PROPER(TEXT(Banco[[#This Row],[Fecha]],"MMMM")) -> Marzo | C40: =TEXT(Banco[[#This Row],[Fecha]],"mmm-yyyy") -> mar-2022 | D40: 44628 | E40: TEF 13790679-1 Paula Paredes | G40: -15816 | H40: =Banco[[#This Row],[cargos]]*-1 -> 15816 | I40: 0 | J40: 16612147 | K40: =+Banco[[#This Row],[cargos]]+Banco[[#This Row],[Ingresos]] -> -15816 | L40: 2.02.08 - Aporte Extraordinario al Socio | M40: =MID(Banco[[#This Row],[CtaCtbl]],FIND(" - ",Banco[[#This Row],[CtaCtbl]])+3,40) -> Aporte Extraordinario al Socio
A41: =YEAR(Banco[[#This Row],[Fecha]]) -> 2022 | B41: =PROPER(TEXT(Banco[[#This Row],[Fecha]],"MMMM")) -> Marzo | C41: =TEXT(Banco[[#This Row],[Fecha]],"mmm-yyyy") -> mar-2022 | D41: 44628 | E41: TEF 76194207-7 Estudio Juridic | G41: -107800 | H41: =Banco[[#This Row],[cargos]]*-1 -> 107800 | I41: 0 | J41: 16502047 | K41: =+Banco[[#This Row],[cargos]]+Banco[[#This Row],[Ingresos]] -> -107800 | L41: 2.01.01.01.1 - Asesoria Legal - Convenio Fijo Mensual | M41: =MID(Banco[[#This Row],[CtaCtbl]],FIND(" - ",Banco[[#This Row],[CtaCtbl]])+3,40) -> Asesoria Legal - Convenio Fijo Mensual | N41: EJ Mes Feb 2022 - Factura N°0254
A42: =YEAR(Banco[[#This Row],[Fecha]]) -> 2022 | B42: =PROPER(TEXT(Banco[[#This Row],[Fecha]],"MMMM")) -> Marzo | C42: =TEXT(Banco[[#This Row],[Fecha]],"mmm-yyyy") -> mar-2022 | D42: 44631 | E42: TEF 76194207-7 Estudio Juridic | G42: -2000000 | H42: =Banco[[#This Row],[cargos]]*-1 -> 2000000 | I42: 0 | J42: 14502047 | K42: =+Banco[[#This Row],[cargos]]+Banco[[#This Row],[Ingresos]] -> -2000000 | L42: 2.01.01.01.2 - Asesoria Legal - Proyectos Negociacion | M42: =MID(Banco[[#This Row],[CtaCtbl]],FIND(" - ",Banco[[#This Row],[CtaCtbl]])+3,40) -> Asesoria Legal - Proyectos Negociacion | N42: EJ Negociacion Colectiva 1er Pago 2022 - Factura N°0251
A43: =YEAR(Banco[[#This Row],[Fecha]]) -> 2022 | B43: =PROPER(TEXT(Banco[[#This Row],[Fecha]],"MMMM")) -> Marzo | C43: =TEXT(Banco[[#This Row],[Fecha]],"mmm-yyyy") -> mar-2022 | D43: 44645 | E43: PROVEEDORE 96505760-9 COLBUN M | G43: 0 | H43: =Banco[[#This Row],[cargos]]*-1 -> 0 | I43: 523512 | K43: =+Banco[[#This Row],[cargos]]+Banco[[#This Row],[Ingresos]] -> 523512 | L43: 1.01.02 - Cuota Extraordinaria | M43: =MID(Banco[[#This Row],[CtaCtbl]],FIND(" - ",Banco[[#This Row],[CtaCtbl]])+3,40) -> Cuota Extraordinaria
A44: =YEAR(Banco[[#This Row],[Fecha]]) -> 2022 | B44: =PROPER(TEXT(Banco[[#This Row],[Fecha]],"MMMM")) -> Marzo | C44: =TEXT(Banco[[#This Row],[Fecha]],"mmm-yyyy") -> mar-2022 | D44: 44645 | E44: PROVEEDORE 96505760-9 COLBUN M | G44: 0 | H44: =Banco[[#This Row],[cargos]]*-1 -> 0 | I44: 3410760 | J44: 18436319 | K44: =+Banco[[#This Row],[cargos]]+Banco[[#This Row],[Ingresos]] -> 3410760 | L44: 1.01.01 - Cuota Ordinaria | M44: =MID(Banco[[#This Row],[CtaCtbl]],FIND(" - ",Banco[[#This Row],[CtaCtbl]])+3,40) -> Cuota Ordinaria
A45: =YEAR(Banco[[#This Row],[Fecha]]) -> 2022 | B45: =PROPER(TEXT(Banco[[#This Row],[Fecha]],"MMMM")) -> Abril | C45: =TEXT(Banco[[#This Row],[Fecha]],"mmm-yyyy") -> abr-2022 | D45: 44652 | E45: COBRO COMISION SCOTIAWEB | G45: -18879 | H45: =Banco[[#This Row],[cargos]]*-1 -> 18879 | I45: 0 | J45: 18417440 | K45: =+Banco[[#This Row],[cargos]]+Banco[[#This Row],[Ingresos]] -> -18879 | L45: 3.03.01 - Pago Comisiones | M45: =MID(Banco[[#This Row],[CtaCtbl]],FIND(" - ",Banco[[#This Row],[CtaCtbl]])+3,40) -> Pago Comisiones
A46: =YEAR(Banco[[#This Row],[Fecha]]) -> 2022 | B46: =PROPER(TEXT(Banco[[#This Row],[Fecha]],"MMMM")) -> Abril | C46: =TEXT(Banco[[#This Row],[Fecha]],"mmm-yyyy") -> abr-2022 | D46: 44655 | E46: TEF 76330590-2 TRANSPORTES JOS | G46: -380572 | H46: =Banco[[#This Row],[cargos]]*-1 -> 380572 | I46: 0 | J46: 18036868 | K46: =+Banco[[#This Row],[cargos]]+Banco[[#This Row],[Ingresos]] -> -380572 | L46: 2.01.03.03.1.7 - Taxi, Uber o Similar | M46: =MID(Banco[[#This Row],[CtaCtbl]],FIND(" - ",Banco[[#This Row],[CtaCtbl]])+3,40) -> Taxi, Uber o Similar
A47: =YEAR(Banco[[#This Row],[Fecha]]) -> 2022 | B47: =PROPER(TEXT(Banco[[#This Row],[Fecha]],"MMMM")) -> Abril | C47: =TEXT(Banco[[#This Row],[Fecha]],"mmm-yyyy") -> abr-2022 | D47: 44677 | E47: PROVEEDORE 96505760-9 COLBUN M | G47: 0 | H47: =Banco[[#This Row],[cargos]]*-1 -> 0 | I47: 3442832 | J47: 21479700 | K47: =+Banco[[#This Row],[cargos]]+Banco[[#This Row],[Ingresos]] -> 3442832 | L47: 1.01.01 - Cuota Ordinaria | M47: =MID(Banco[[#This Row],[CtaCtbl]],FIND(" - ",Banco[[#This Row],[CtaCtbl]])+3,40) -> Cuota Ordinaria
A48: =YEAR(Banco[[#This Row],[Fecha]]) -> 2022 | B48: =PROPER(TEXT(Banco[[#This Row],[Fecha]],"MMMM")) -> Abril | C48: =TEXT(Banco[[#This Row],[Fecha]],"mmm-yyyy") -> abr-2022 | D48: 44677 | E48: TEF 12379484-2 Abdel Karim Aza | G48: -63463 | H48: =Banco[[#This Row],[cargos]]*-1 -> 63463 | I48: 0 | J48: 18016379 | K48: =+Banco[[#This Row],[cargos]]+Banco[[#This Row],[Ingresos]] -> -63463 | L48: 2.01.04.03 - Otros gastos varios | M48: =MID(Banco[[#This Row],[CtaCtbl]],FIND(" - ",Banco[[#This Row],[CtaCtbl]])+3,40) -> Otros gastos varios
A49: =YEAR(Banco[[#This Row],[Fecha]]) -> 2022 | B49: =PROPER(TEXT(Banco[[#This Row],[Fecha]],"MMMM")) -> Abril | C49: =TEXT(Banco[[#This Row],[Fecha]],"mmm-yyyy") -> abr-2022 | D49: 44677 | E49: TEF 12846913-3 Mitchell Zuniga | G49: -15606 | H49: =Banco[[#This Row],[cargos]]*-1 -> 15606 | I49: 0 | J49: 18242494 | K49: =+Banco[[#This Row],[cargos]]+Banco[[#This Row],[Ingresos]] -> -15606 | L49: 2.02.05 - Restitución Fondos Socios | M49: =MID(Banco[[#This Row],[CtaCtbl]],FIND(" - ",Banco[[#This Row],[CtaCtbl]])+3,40) -> Restitución Fondos Socios
...

Sheet Plan de Cuentas
E2: 2021 | J2: 2022 | W2: 2023 | AJ2: 2024 | AV2: 2024 | AW2: 2025 | BI2: 2025 | BW2: Resultado
A3: Cuenta | B3: Descripcion Cuenta | C3: Codigo Cta | D3: Observaciones | E3: sept-21 | F3: oct-21 | G3: nov-21 | H3: dic-21 | I3: Total 2021 | J3: ene-22 | K3: feb-22 | L3: mar-22 | M3: abr-22 | N3: may-22 | O3: jun-22 | P3: jul-22 | Q3: ago-22 | R3: sept-22 | S3: oct-22 | T3: nov-22 | U3: dic-22 | V3: Total 2022 | W3: ene-23 | X3: feb-23 | Y3: mar-23 | Z3: abr-23 | AA3: may-23 | AB3: jun-23 | AC3: jul-23 | AD3: ago-23 | AE3: sept-23 | AF3: oct-23 | AG3: nov-23 | AH3: dic-23 | AI3: Total 2023 | AJ3: ene-24 | AK3: feb-24 | AL3: mar-24 | AM3: abr-24 | AN3: may-24 | AO3: jun-24 | AP3: jul-24 | AQ3: ago-24 | AR3: sept-24 | AS3: oct-24 | AT3: nov-24 | AU3: dic-24 | AV3: Total 2024 | AW3: ene-25 | AX3: feb-25 | AY3: mar-25 | AZ3: abr-25 | BA3: may-25 | BB3: jun-25 | BC3: jul-25 | BD3: ago-25 | BE3: sept-25 | BF3: oct-25 | BG3: nov-25 | BH3: dic-25 | BI3: Total 2025 | BJ3: ene-26 | BK3: feb-26 | BL3: mar-26 | BM3: abr-26 | BN3: may-26 | BO3: jun-26 | BP3: jul-26 | BQ3: ago-26 | BR3: sept-26 | BS3: oct-26 | BT3: nov-26 | BU3: dic-26 | BV3: Total 2026 | BW3: Total
A4: 1 | B4: Ingresos | C4: =+Tabla17[[#This Row],[Cuenta]]&" - "&Tabla17[[#This Row],[Descripcion Cuenta]] -> 1 - Ingresos | E4: =SUBTOTAL(9,E5:E24) -> 0 | F4: =SUBTOTAL(9,F5:F24) -> 6794912 | G4: =SUBTOTAL(9,G5:G24) -> 2584008 | H4: =SUBTOTAL(9,H5:H24) -> 2882256 | I4: =SUM(Tabla17[[#This Row],[sept-21]:[dic-21]]) -> 12261176 | J4: =SUBTOTAL(9,J5:J24) -> 2840292 | K4: =SUBTOTAL(9,K5:K24) -> 3200162 | L4: =SUBTOTAL(9,L5:L24) -> 3934272 | M4: =SUBTOTAL(9,M5:M24) -> 3442832 | N4: =SUBTOTAL(9,N5:N24) -> 110496760 | O4: =SUBTOTAL(9,O5:O24) -> 6589603 | P4: =SUBTOTAL(9,P5:P24) -> 3592435 | Q4: =SUBTOTAL(9,Q5:Q24) -> 3603534 | ... BW4: =SUBTOTAL(9,BW5:BW24) -> 0
A5: 1.01 | B5: Cuotas Sindicales | C5: =+Tabla17[[#This Row],[Cuenta]]&" - "&Tabla17[[#This Row],[Descripcion Cuenta]] -> 1.01 - Cuotas Sindicales | E5: =SUBTOTAL(9,E6:E8) -> 0 | F5: =SUBTOTAL(9,F6:F8) -> 6794912 | G5: =SUBTOTAL(9,G6:G8) -> 2584008 | H5: =SUBTOTAL(9,H6:H8) -> 2882256 | I5: =SUM(Tabla17[[#This Row],[sept-21]:[dic-21]]) -> 12261176 | J5: =SUBTOTAL(9,J6:J8) -> 2840292 | K5: =SUBTOTAL(9,K6:K8) -> 3200162 | L5: =SUBTOTAL(9,L6:L8) -> 3934272 | M5: =SUBTOTAL(9,M6:M8) -> 3442832 | N5: =SUBTOTAL(9,N6:N8) -> 3496760 | O5: =SUBTOTAL(9,O6:O8) -> 3589603 | P5: =SUBTOTAL(9,P6:P8) -> 3592435 | Q5: =SUBTOTAL(9,Q6:Q8) -> 3603534 | ... BW5: =SUBTOTAL(9,BW6:BW8) -> 0
A6: 1.01.01 | B6: Cuota Ordinaria | C6: =+Tabla17[[#This Row],[Cuenta]]&" - "&Tabla17[[#This Row],[Descripcion Cuenta]] -> 1.01.01 - Cuota Ordinaria | E6: =SUMIFS(Banco[Monto],Banco[CtaCtbl],$C6,Banco[Periodo Contable],TEXT(E$3,"mmm-yyyy")) -> 0 | F6: =SUMIFS(Banco[Monto],Banco[CtaCtbl],$C6,Banco[Periodo Contable],TEXT(F$3,"mmm-yyyy")) -> 4445566 | G6: =SUMIFS(Banco[Monto],Banco[CtaCtbl],$C6,Banco[Periodo Contable],TEXT(G$3,"mmm-yyyy")) -> 2476341 | H6: =SUMIFS(Banco[Monto],Banco[CtaCtbl],$C6,Banco[Periodo Contable],TEXT(H$3,"mmm-yyyy")) -> 2665312 | I6: =SUM(Tabla17[[#This Row],[sept-21]:[dic-21]]) -> 9587219 | J6: =SUMIFS(Banco[Monto],Banco[CtaCtbl],$C6,Banco[Periodo Contable],TEXT(J$3,"mmm-yyyy")) -> 2731050 | K6: =SUMIFS(Banco[Monto],Banco[CtaCtbl],$C6,Banco[Periodo Contable],TEXT(K$3,"mmm-yyyy")) -> 2917450 | L6: =SUMIFS(Banco[Monto],Banco[CtaCtbl],$C6,Banco[Periodo Contable],TEXT(L$3,"mmm-yyyy")) -> 3410760 | M6: =SUMIFS(Banco[Monto],Banco[CtaCtbl],$C6,Banco[Periodo Contable],TEXT(M$3,"mmm-yyyy")) -> 3442832 | N6: =SUMIFS(Banco[Monto],Banco[CtaCtbl],$C6,Banco[Periodo Contable],TEXT(N$3,"mmm-yyyy")) -> 3496760 | O6: =SUMIFS(Banco[Monto],Banco[CtaCtbl],$C6,Banco[Periodo Contable],TEXT(O$3,"mmm-yyyy")) -> 3507116 | P6: =SUMIFS(Banco[Monto],Banco[CtaCtbl],$C6,Banco[Periodo Contable],TEXT(P$3,"mmm-yyyy")) -> 3592435 | Q6: =SUMIFS(Banco[Monto],Banco[CtaCtbl],$C6,Banco[Periodo Contable],TEXT(Q$3,"mmm-yyyy")) -> 3603534 | ... U6: =SUMIFS(Banco[Monto],Banco[CtaCtbl],$C6,Banco[Periodo Contable],TEXT(U$3,"mmm-yyyy")) -> 3633885 | V6: =SUM(Tabla17[[#This Row],[ene-22]:[dic-22]]) -> 41203147 | W6: =SUMIFS(Banco[Monto],Banco[CtaCtbl],$C6,Banco[Periodo Contable],TEXT(W$3,"mmm-yyyy")) -> 3617020 | X6: =SUMIFS(Banco[Monto],Banco[CtaCtbl],$C6,Banco[Periodo Contable],TEXT(X$3,"mmm-yyyy")) -> 3622020 | Y6: =SUMIFS(Banco[Monto],Banco[CtaCtbl],$C6,Banco[Periodo Contable],TEXT(Y$3,"mmm-yyyy")) -> 3610964 | Z6: =SUMIFS(Banco[Monto],Banco[CtaCtbl],$C6,Banco[Periodo Contable],TEXT(Z$3,"mmm-yyyy")) -> 3619638 | AA6: =SUMIFS(Banco[Monto],Banco[CtaCtbl],$C6,Banco[Periodo Contable],TEXT(AA$3,"mmm-yyyy")) -> 3603200 | AB6: =SUMIFS(Banco[Monto],Banco[CtaCtbl],$C6,Banco[Periodo Contable],TEXT(AB$3,"mmm-yyyy")) -> 3609000 | AC6: =SUMIFS(Banco[Monto],Banco[CtaCtbl],$C6,Banco[Periodo Contable],TEXT(AC$3,"mmm-yyyy")) -> 3623016 | AD6: =SUMIFS(Banco[Monto],Banco[CtaCtbl],$C6,Banco[Periodo Contable],TEXT(AD$3,"mmm-yyyy")) -> 3594935 | ... AH6: =SUMIFS(Banco[Monto],Banco[CtaCtbl],$C6,Banco[Periodo Contable],TEXT(AH$3,"mmm-yyyy")) -> 3605420 | AI6: =SUM(Tabla17[[#This Row],[ene-23]:[dic-23]]) -> 43310880 | AJ6: =SUMIFS(Banco[Monto],Banco[CtaCtbl],$C6,Banco[Periodo Contable],TEXT(AJ$3,"mmm-yyyy")) -> 3618299 | AK6: =SUMIFS(Banco[Monto],Banco[CtaCtbl],$C6,Banco[Periodo Contable],TEXT(AK$3,"mmm-yyyy")) -> 3611888 | AL6: =SUMIFS(Banco[Monto],Banco[CtaCtbl],$C6,Banco[Periodo Contable],TEXT(AL$3,"mmm-yyyy")) -> 3635212 | AM6: =SUMIFS(Banco[Monto],Banco[CtaCtbl],$C6,Banco[Periodo Contable],TEXT(AM$3,"mmm-yyyy")) -> 3688938 | AN6: =SUMIFS(Banco[Monto],Banco[CtaCtbl],$C6,Banco[Periodo Contable],TEXT(AN$3,"mmm-yyyy")) -> 3650205 | AO6: =SUMIFS(Banco[Monto],Banco[CtaCtbl],$C6,Banco[Periodo Contable],TEXT(AO$3,"mmm-yyyy")) -> 3644484 | AP6: =SUMIFS(Banco[Monto],Banco[CtaCtbl],$C6,Banco[Periodo Contable],TEXT(AP$3,"mmm-yyyy")) -> 3626277 | AQ6: =SUMIFS(Banco[Monto],Banco[CtaCtbl],$C6,Banco[Periodo Contable],TEXT(AQ$3,"mmm-yyyy")) -> 3643261 | ... AU6: =SUMIFS(Banco[Monto],Banco[CtaCtbl],$C6,Banco[Periodo Contable],TEXT(AU$3,"mmm-yyyy")) -> 5128536 | AV6: =SUM(Tabla17[[#This Row],[ene-24]:[dic-24]]) -> 45984735 | AW6: =SUMIFS(Banco[Monto],Banco[CtaCtbl],$C6,Banco[Periodo Contable],TEXT(AW$3,"mmm-yyyy")) -> 5047496 | AX6: =SUMIFS(Banco[Monto],Banco[CtaCtbl],$C6,Banco[Periodo Contable],TEXT(AX$3,"mmm-yyyy")) -> 8599180 | AY6: =SUMIFS(Banco[Monto],Banco[CtaCtbl],$C6,Banco[Periodo Contable],TEXT(AY$3,"mmm-yyyy")) -> 9373454 | AZ6: =SUMIFS(Banco[Monto],Banco[CtaCtbl],$C6,Banco[Periodo Contable],TEXT(AZ$3,"mmm-yyyy")) -> 9417316 | BA6: =SUMIFS(Banco[Monto],Banco[CtaCtbl],$C6,Banco[Periodo Contable],TEXT(BA$3,"mmm-yyyy")) -> 9366410 | BB6: =SUMIFS(Banco[Monto],Banco[CtaCtbl],$C6,Banco[Periodo Contable],TEXT(BB$3,"mmm-yyyy")) -> 9286882 | BC6: =SUMIFS(Banco[Monto],Banco[CtaCtbl],$C6,Banco[Periodo Contable],TEXT(BC$3,"mmm-yyyy")) -> 9187710 | BD6: =SUMIFS(Banco[Monto],Banco[CtaCtbl],$C6,Banco[Periodo Contable],TEXT(BD$3,"mmm-yyyy")) -> 9156780 | ... BH6: =SUMIFS(Banco[Monto],Banco[CtaCtbl],$C6,Banco[Periodo Contable],TEXT(BH$3,"mmm-yyyy")) -> 8938800 | BI6: =SUM(Tabla17[[#This Row],[ene-25]:[dic-25]]) -> 96415352 | BJ6: =SUMIFS(Banco[Monto],Banco[CtaCtbl],$C6,Banco[Periodo Contable],TEXT(BJ$3,"mmm-yyyy")) -> 8933850 | BK6: =SUMIFS(Banco[Monto],Banco[CtaCtbl],$C6,Banco[Periodo Contable],TEXT(BK$3,"mmm-yyyy")) -> 8455375 | BL6: =SUMIFS(Banco[Monto],Banco[CtaCtbl],$C6,Banco[Periodo Contable],TEXT(BL$3,"mmm-yyyy")) -> 0 | BM6: =SUMIFS(Banco[Monto],Banco[CtaCtbl],$C6,Banco[Periodo Contable],TEXT(BM$3,"mmm-yyyy")) -> 0 | BN6: =SUMIFS(Banco[Monto],Banco[CtaCtbl],$C6,Banco[Periodo Contable],TEXT(BN$3,"mmm-yyyy")) -> 0 | BO6: =SUMIFS(Banco[Monto],Banco[CtaCtbl],$C6,Banco[Periodo Contable],TEXT(BO$3,"mmm-yyyy")) -> 0 | BP6: =SUMIFS(Banco[Monto],Banco[CtaCtbl],$C6,Banco[Periodo Contable],TEXT(BP$3,"mmm-yyyy")) -> 0 | BQ6: =SUMIFS(Banco[Monto],Banco[CtaCtbl],$C6,Banco[Periodo Contable],TEXT(BQ$3,"mmm-yyyy")) -> 0 | ... BU6: =SUMIFS(Banco[Monto],Banco[CtaCtbl],$C6,Banco[Periodo Contable],TEXT(BU$3,"mmm-yyyy")) -> 0 | BV6: =SUM(Tabla17[[#This Row],[ene-26]:[dic-26]]) -> 17389225 | BW6: =SUMIFS(Banco[Monto],Banco[CtaCtbl],$C6,Banco[Periodo Contable],TEXT(BW$3,"mmm-yyyy")) -> 0
A7: 1.01.02 | B7: Cuota Extraordinaria | C7: =+Tabla17[[#This Row],[Cuenta]]&" - "&Tabla17[[#This Row],[Descripcion Cuenta]] -> 1.01.02 - Cuota Extraordinaria | E7: =SUMIFS(Banco[Monto],Banco[CtaCtbl],$C7,Banco[Periodo Contable],TEXT(E$3,"mmm-yyyy")) -> 0 | F7: =SUMIFS(Banco[Monto],Banco[CtaCtbl],$C7,Banco[Periodo Contable],TEXT(F$3,"mmm-yyyy")) -> 2349346 | G7: =SUMIFS(Banco[Monto],Banco[CtaCtbl],$C7,Banco[Periodo Contable],TEXT(G$3,"mmm-yyyy")) -> 107667 | H7: =SUMIFS(Banco[Monto],Banco[CtaCtbl],$C7,Banco[Periodo Contable],TEXT(H$3,"mmm-yyyy")) -> 216944 | I7: =SUM(Tabla17[[#This Row],[sept-21]:[dic-21]]) -> 2673957 | J7: =SUMIFS(Banco[Monto],Banco[CtaCtbl],$C7,Banco[Periodo Contable],TEXT(J$3,"mmm-yyyy")) -> 109242 | K7: =SUMIFS(Banco[Monto],Banco[CtaCtbl],$C7,Banco[Periodo Contable],TEXT(K$3,"mmm-yyyy")) -> 282712 | L7: =SUMIFS(Banco[Monto],Banco[CtaCtbl],$C7,Banco[Periodo Contable],TEXT(L$3,"mmm-yyyy")) -> 523512 | M7: =SUMIFS(Banco[Monto],Banco[CtaCtbl],$C7,Banco[Periodo Contable],TEXT(M$3,"mmm-yyyy")) -> 0 | N7: =SUMIFS(Banco[Monto],Banco[CtaCtbl],$C7,Banco[Periodo Contable],TEXT(N$3,"mmm-yyyy")) -> 0 | O7: =SUMIFS(Banco[Monto],Banco[CtaCtbl],$C7,Banco[Periodo Contable],TEXT(O$3,"mmm-yyyy")) -> 82487 | P7: =SUMIFS(Banco[Monto],Banco[CtaCtbl],$C7,Banco[Periodo Contable],TEXT(P$3,"mmm-yyyy")) -> 0 | Q7: =SUMIFS(Banco[Monto],Banco[CtaCtbl],$C7,Banco[Periodo Contable],TEXT(Q$3,"mmm-yyyy")) -> 0 | ... U7: =SUMIFS(Banco[Monto],Banco[CtaCtbl],$C7,Banco[Periodo Contable],TEXT(U$3,"mmm-yyyy")) -> 0 | V7: =SUM(Tabla17[[#This Row],[ene-22]:[dic-22]]) -> 997953 | W7: =SUMIFS(Banco[Monto],Banco[CtaCtbl],$C7,Banco[Periodo Contable],TEXT(W$3,"mmm-yyyy")) -> 0 | X7: =SUMIFS(Banco[Monto],Banco[CtaCtbl],$C7,Banco[Periodo Contable],TEXT(X$3,"mmm-yyyy")) -> 0 | Y7: =SUMIFS(Banco[Monto],Banco[CtaCtbl],$C7,Banco[Periodo Contable],TEXT(Y$3,"mmm-yyyy")) -> 0 | Z7: =SUMIFS(Banco[Monto],Banco[CtaCtbl],$C7,Banco[Periodo Contable],TEXT(Z$3,"mmm-yyyy")) -> 2134184 | AA7: =SUMIFS(Banco[Monto],Banco[CtaCtbl],$C7,Banco[Periodo Contable],TEXT(AA$3,"mmm-yyyy")) -> 0 | AB7: =SUMIFS(Banco[Monto],Banco[CtaCtbl],$C7,Banco[Periodo Contable],TEXT(AB$3,"mmm-yyyy")) -> 0 | AC7: =SUMIFS(Banco[Monto],Banco[CtaCtbl],$C7,Banco[Periodo Contable],TEXT(AC$3,"mmm-yyyy")) -> 0 | AD7: =SUMIFS(Banco[Monto],Banco[CtaCtbl],$C7,Banco[Periodo Contable],TEXT(AD$3,"mmm-yyyy")) -> 18025 | ... AH7: =SUMIFS(Banco[Monto],Banco[CtaCtbl],$C7,Banco[Periodo Contable],TEXT(AH$3,"mmm-yyyy")) -> 18282 | AI7: =SUM(Tabla17[[#This Row],[ene-23]:[dic-23]]) -> 2466551 | AJ7: =SUMIFS(Banco[Monto],Banco[CtaCtbl],$C7,Banco[Periodo Contable],TEXT(AJ$3,"mmm-yyyy")) -> 36649 | AK7: =SUMIFS(Banco[Monto],Banco[CtaCtbl],$C7,Banco[Periodo Contable],TEXT(AK$3,"mmm-yyyy")) -> 18282 | AL7: =SUMIFS(Banco[Monto],Banco[CtaCtbl],$C7,Banco[Periodo Contable],TEXT(AL$3,"mmm-yyyy")) -> 2257607 | AM7: =SUMIFS(Banco[Monto],Banco[CtaCtbl],$C7,Banco[Periodo Contable],TEXT(AM$3,"mmm-yyyy")) -> 92806 | AN7: =SUMIFS(Banco[Monto],Banco[CtaCtbl],$C7,Banco[Periodo Contable],TEXT(AN$3,"mmm-yyyy")) -> 18282 | AO7: =SUMIFS(Banco[Monto],Banco[CtaCtbl],$C7,Banco[Periodo Contable],TEXT(AO$3,"mmm-yyyy")) -> 18282 | AP7: =SUMIFS(Banco[Monto],Banco[CtaCtbl],$C7,Banco[Periodo Contable],TEXT(AP$3,"mmm-yyyy")) -> 18282 | AQ7: =SUMIFS(Banco[Monto],Banco[CtaCtbl],$C7,Banco[Periodo Contable],TEXT(AQ$3,"mmm-yyyy")) -> 18282 | ... AU7: =SUMIFS(Banco[Monto],Banco[CtaCtbl],$C7,Banco[Periodo Contable],TEXT(AU$3,"mmm-yyyy")) -> 1450664 | AV7: =SUM(Tabla17[[#This Row],[ene-24]:[dic-24]]) -> 3983982 | AW7: =SUMIFS(Banco[Monto],Banco[CtaCtbl],$C7,Banco[Periodo Contable],TEXT(AW$3,"mmm-yyyy")) -> 0 | AX7: =SUMIFS(Banco[Monto],Banco[CtaCtbl],$C7,Banco[Periodo Contable],TEXT(AX$3,"mmm-yyyy")) -> 3594264 | AY7: =SUMIFS(Banco[Monto],Banco[CtaCtbl],$C7,Banco[Periodo Contable],TEXT(AY$3,"mmm-yyyy")) -> 738986 | AZ7: =SUMIFS(Banco[Monto],Banco[CtaCtbl],$C7,Banco[Periodo Contable],TEXT(AZ$3,"mmm-yyyy")) -> 0 | BA7: =SUMIFS(Banco[Monto],Banco[CtaCtbl],$C7,Banco[Periodo Contable],TEXT(BA$3,"mmm-yyyy")) -> 0 | BB7: =SUMIFS(Banco[Monto],Banco[CtaCtbl],$C7,Banco[Periodo Contable],TEXT(BB$3,"mmm-yyyy")) -> 0 | BC7: =SUMIFS(Banco[Monto],Banco[CtaCtbl],$C7,Banco[Periodo Contable],TEXT(BC$3,"mmm-yyyy")) -> 0 | BD7: =SUMIFS(Banco[Monto],Banco[CtaCtbl],$C7,Banco[Periodo Contable],TEXT(BD$3,"mmm-yyyy")) -> 0 | ... BH7: =SUMIFS(Banco[Monto],Banco[CtaCtbl],$C7,Banco[Periodo Contable],TEXT(BH$3,"mmm-yyyy")) -> 0 | BI7: =SUM(Tabla17[[#This Row],[ene-25]:[dic-25]]) -> 4333250 | BJ7: =SUMIFS(Banco[Monto],Banco[CtaCtbl],$C7,Banco[Periodo Contable],TEXT(BJ$3,"mmm-yyyy")) -> 0 | BK7: =SUMIFS(Banco[Monto],Banco[CtaCtbl],$C7,Banco[Periodo Contable],TEXT(BK$3,"mmm-yyyy")) -> 0 | BL7: =SUMIFS(Banco[Monto],Banco[CtaCtbl],$C7,Banco[Periodo Contable],TEXT(BL$3,"mmm-yyyy")) -> 0 | BM7: =SUMIFS(Banco[Monto],Banco[CtaCtbl],$C7,Banco[Periodo Contable],TEXT(BM$3,"mmm-yyyy")) -> 0 | BN7: =SUMIFS(Banco[Monto],Banco[CtaCtbl],$C7,Banco[Periodo Contable],TEXT(BN$3,"mmm-yyyy")) -> 0 | BO7: =SUMIFS(Banco[Monto],Banco[CtaCtbl],$C7,Banco[Periodo Contable],TEXT(BO$3,"mmm-yyyy")) -> 0 | BP7: =SUMIFS(Banco[Monto],Banco[CtaCtbl],$C7,Banco[Periodo Contable],TEXT(BP$3,"mmm-yyyy")) -> 0 | BQ7: =SUMIFS(Banco[Monto],Banco[CtaCtbl],$C7,Banco[Periodo Contable],TEXT(BQ$3,"mmm-yyyy")) -> 0 | ... BU7: =SUMIFS(Banco[Monto],Banco[CtaCtbl],$C7,Banco[Periodo Contable],TEXT(BU$3,"mmm-yyyy")) -> 0 | BV7: =SUM(Tabla17[[#This Row],[ene-26]:[dic-26]]) -> 0 | BW7: =SUMIFS(Banco[Monto],Banco[CtaCtbl],$C7,Banco[Periodo Contable],TEXT(BW$3,"mmm-yyyy")) -> 0
A8: 1.01.03 | C8: =+Tabla17[[#This Row],[Cuenta]]&" - "&Tabla17[[#This Row],[Descripcion Cuenta]] -> 1.01.03 - | E8: =SUMIFS(Banco[Monto],Banco[CtaCtbl],$C8,Banco[Periodo Contable],TEXT(E$3,"mmm-yyyy")) -> 0 | F8: =SUMIFS(Banco[Monto],Banco[CtaCtbl],$C8,Banco[Periodo Contable],TEXT(F$3,"mmm-yyyy")) -> 0 | G8: =SUMIFS(Banco[Monto],Banco[CtaCtbl],$C8,Banco[Periodo Contable],TEXT(G$3,"mmm-yyyy")) -> 0 | H8: =SUMIFS(Banco[Monto],Banco[CtaCtbl],$C8,Banco[Periodo Contable],TEXT(H$3,"mmm-yyyy")) -> 0 | I8: =SUM(Tabla17[[#This Row],[sept-21]:[dic-21]]) -> 0 | J8: =SUMIFS(Banco[Monto],Banco[CtaCtbl],$C8,Banco[Periodo Contable],TEXT(J$3,"mmm-yyyy")) -> 0 | K8: =SUMIFS(Banco[Monto],Banco[CtaCtbl],$C8,Banco[Periodo Contable],TEXT(K$3,"mmm-yyyy")) -> 0 | L8: =SUMIFS(Banco[Monto],Banco[CtaCtbl],$C8,Banco[Periodo Contable],TEXT(L$3,"mmm-yyyy")) -> 0 | M8: =SUMIFS(Banco[Monto],Banco[CtaCtbl],$C8,Banco[Periodo Contable],TEXT(M$3,"mmm-yyyy")) -> 0 | N8: =SUMIFS(Banco[Monto],Banco[CtaCtbl],$C8,Banco[Periodo Contable],TEXT(N$3,"mmm-yyyy")) -> 0 | O8: =SUMIFS(Banco[Monto],Banco[CtaCtbl],$C8,Banco[Periodo Contable],TEXT(O$3,"mmm-yyyy")) -> 0 | P8: =SUMIFS(Banco[Monto],Banco[CtaCtbl],$C8,Banco[Periodo Contable],TEXT(P$3,"mmm-yyyy")) -> 0 | Q8: =SUMIFS(Banco[Monto],Banco[CtaCtbl],$C8,Banco[Periodo Contable],TEXT(Q$3,"mmm-yyyy")) -> 0 | ... U8: =SUMIFS(Banco[Monto],Banco[CtaCtbl],$C8,Banco[Periodo Contable],TEXT(U$3,"mmm-yyyy")) -> 0 | V8: =SUM(Tabla17[[#This Row],[ene-22]:[dic-22]]) -> 0 | W8: =SUMIFS(Banco[Monto],Banco[CtaCtbl],$C8,Banco[Periodo Contable],TEXT(W$3,"mmm-yyyy")) -> 0 | X8: =SUMIFS(Banco[Monto],Banco[CtaCtbl],$C8,Banco[Periodo Contable],TEXT(X$3,"mmm-yyyy")) -> 0 | Y8: =SUMIFS(Banco[Monto],Banco[CtaCtbl],$C8,Banco[Periodo Contable],TEXT(Y$3,"mmm-yyyy")) -> 0 | Z8: =SUMIFS(Banco[Monto],Banco[CtaCtbl],$C8,Banco[Periodo Contable],TEXT(Z$3,"mmm-yyyy")) -> 0 | AA8: =SUMIFS(Banco[Monto],Banco[CtaCtbl],$C8,Banco[Periodo Contable],TEXT(AA$3,"mmm-yyyy")) -> 0 | AB8: =SUMIFS(Banco[Monto],Banco[CtaCtbl],$C8,Banco[Periodo Contable],TEXT(AB$3,"mmm-yyyy")) -> 0 | AC8: =SUMIFS(Banco[Monto],Banco[CtaCtbl],$C8,Banco[Periodo Contable],TEXT(AC$3,"mmm-yyyy")) -> 0 | AD8: =SUMIFS(Banco[Monto],Banco[CtaCtbl],$C8,Banco[Periodo Contable],TEXT(AD$3,"mmm-yyyy")) -> 0 | ... AH8: =SUMIFS(Banco[Monto],Banco[CtaCtbl],$C8,Banco[Periodo Contable],TEXT(AH$3,"mmm-yyyy")) -> 0 | AI8: =SUM(Tabla17[[#This Row],[ene-23]:[dic-23]]) -> 0 | AJ8: =SUMIFS(Banco[Monto],Banco[CtaCtbl],$C8,Banco[Periodo Contable],TEXT(AJ$3,"mmm-yyyy")) -> 0 | AK8: =SUMIFS(Banco[Monto],Banco[CtaCtbl],$C8,Banco[Periodo Contable],TEXT(AK$3,"mmm-yyyy")) -> 0 | AL8: =SUMIFS(Banco[Monto],Banco[CtaCtbl],$C8,Banco[Periodo Contable],TEXT(AL$3,"mmm-yyyy")) -> 0 | AM8: =SUMIFS(Banco[Monto],Banco[CtaCtbl],$C8,Banco[Periodo Contable],TEXT(AM$3,"mmm-yyyy")) -> 0 | AN8: =SUMIFS(Banco[Monto],Banco[CtaCtbl],$C8,Banco[Periodo Contable],TEXT(AN$3,"mmm-yyyy")) -> 0 | AO8: =SUMIFS(Banco[Monto],Banco[CtaCtbl],$C8,Banco[Periodo Contable],TEXT(AO$3,"mmm-yyyy")) -> 0 | AP8: =SUMIFS(Banco[Monto],Banco[CtaCtbl],$C8,Banco[Periodo Contable],TEXT(AP$3,"mmm-yyyy")) -> 0 | AQ8: =SUMIFS(Banco[Monto],Banco[CtaCtbl],$C8,Banco[Periodo Contable],TEXT(AQ$3,"mmm-yyyy")) -> 0 | ... AU8: =SUMIFS(Banco[Monto],Banco[CtaCtbl],$C8,Banco[Periodo Contable],TEXT(AU$3,"mmm-yyyy")) -> 0 | AV8: =SUM(Tabla17[[#This Row],[ene-24]:[dic-24]]) -> 0 | AW8: =SUMIFS(Banco[Monto],Banco[CtaCtbl],$C8,Banco[Periodo Contable],TEXT(AW$3,"mmm-yyyy")) -> 0 | AX8: =SUMIFS(Banco[Monto],Banco[CtaCtbl],$C8,Banco[Periodo Contable],TEXT(AX$3,"mmm-yyyy")) -> 0 | AY8: =SUMIFS(Banco[Monto],Banco[CtaCtbl],$C8,Banco[Periodo Contable],TEXT(AY$3,"mmm-yyyy")) -> 0 | AZ8: =SUMIFS(Banco[Monto],Banco[CtaCtbl],$C8,Banco[Periodo Contable],TEXT(AZ$3,"mmm-yyyy")) -> 0 | BA8: =SUMIFS(Banco[Monto],Banco[CtaCtbl],$C8,Banco[Periodo Contable],TEXT(BA$3,"mmm-yyyy")) -> 0 | BB8: =SUMIFS(Banco[Monto],Banco[CtaCtbl],$C8,Banco[Periodo Contable],TEXT(BB$3,"mmm-yyyy")) -> 0 | BC8: =SUMIFS(Banco[Monto],Banco[CtaCtbl],$C8,Banco[Periodo Contable],TEXT(BC$3,"mmm-yyyy")) -> 0 | BD8: =SUMIFS(Banco[Monto],Banco[CtaCtbl],$C8,Banco[Periodo Contable],TEXT(BD$3,"mmm-yyyy")) -> 0 | ... BH8: =SUMIFS(Banco[Monto],Banco[CtaCtbl],$C8,Banco[Periodo Contable],TEXT(BH$3,"mmm-yyyy")) -> 0 | BI8: =SUM(Tabla17[[#This Row],[ene-25]:[dic-25]]) -> 0 | BJ8: =SUMIFS(Banco[Monto],Banco[CtaCtbl],$C8,Banco[Periodo Contable],TEXT(BJ$3,"mmm-yyyy")) -> 0 | BK8: =SUMIFS(Banco[Monto],Banco[CtaCtbl],$C8,Banco[Periodo Contable],TEXT(BK$3,"mmm-yyyy")) -> 0 | BL8: =SUMIFS(Banco[Monto],Banco[CtaCtbl],$C8,Banco[Periodo Contable],TEXT(BL$3,"mmm-yyyy")) -> 0 | BM8: =SUMIFS(Banco[Monto],Banco[CtaCtbl],$C8,Banco[Periodo Contable],TEXT(BM$3,"mmm-yyyy")) -> 0 | BN8: =SUMIFS(Banco[Monto],Banco[CtaCtbl],$C8,Banco[Periodo Contable],TEXT(BN$3,"mmm-yyyy")) -> 0 | BO8: =SUMIFS(Banco[Monto],Banco[CtaCtbl],$C8,Banco[Periodo Contable],TEXT(BO$3,"mmm-yyyy")) -> 0 | BP8: =SUMIFS(Banco[Monto],Banco[CtaCtbl],$C8,Banco[Periodo Contable],TEXT(BP$3,"mmm-yyyy")) -> 0 | BQ8: =SUMIFS(Banco[Monto],Banco[CtaCtbl],$C8,Banco[Periodo Contable],TEXT(BQ$3,"mmm-yyyy")) -> 0 | ... BU8: =SUMIFS(Banco[Monto],Banco[CtaCtbl],$C8,Banco[Periodo Contable],TEXT(BU$3,"mmm-yyyy")) -> 0 | BV8: =SUM(Tabla17[[#This Row],[ene-26]:[dic-26]]) -> 0 | BW8: =SUMIFS(Banco[Monto],Banco[CtaCtbl],$C8,Banco[Periodo Contable],TEXT(BW$3,"mmm-yyyy")) -> 0
A9: 1.02 | B9: Multas | C9: =+Tabla17[[#This Row],[Cuenta]]&" - "&Tabla17[[#This Row],[Descripcion Cuenta]] -> 1.02 - Multas | E9: =SUBTOTAL(9,E10:E11) -> 0 | F9: =SUBTOTAL(9,F10:F11) -> 0 | G9: =SUBTOTAL(9,G10:G11) -> 0 | H9: =SUBTOTAL(9,H10:H11) -> 0 | I9: =SUM(Tabla17[[#This Row],[sept-21]:[dic-21]]) -> 0 | J9: =SUBTOTAL(9,J10:J11) -> 0 | K9: =SUBTOTAL(9,K10:K11) -> 0 | L9: =SUBTOTAL(9,L10:L11) -> 0 | M9: =SUBTOTAL(9,M10:M11) -> 0 | N9: =SUBTOTAL(9,N10:N11) -> 0 | O9: =SUBTOTAL(9,O10:O11) -> 0 | P9: =SUBTOTAL(9,P10:P11) -> 0 | Q9: =SUBTOTAL(9,Q10:Q11) -> 0 | ... BW9: =SUBTOTAL(9,BW10:BW11) -> 0
A10: 1.02.01 | B10: Multa Inasistencia | C10: =+Tabla17[[#This Row],[Cuenta]]&" - "&Tabla17[[#This Row],[Descripcion Cuenta]] -> 1.02.01 - Multa Inasistencia | E10: =SUMIFS(Banco[Monto],Banco[CtaCtbl],$C10,Banco[Periodo Contable],TEXT(E$3,"mmm-yyyy")) -> 0 | F10: =SUMIFS(Banco[Monto],Banco[CtaCtbl],$C10,Banco[Periodo Contable],TEXT(F$3,"mmm-yyyy")) -> 0 | G10: =SUMIFS(Banco[Monto],Banco[CtaCtbl],$C10,Banco[Periodo Contable],TEXT(G$3,"mmm-yyyy")) -> 0 | H10: =SUMIFS(Banco[Monto],Banco[CtaCtbl],$C10,Banco[Periodo Contable],TEXT(H$3,"mmm-yyyy")) -> 0 | I10: =SUM(Tabla17[[#This Row],[sept-21]:[dic-21]]) -> 0 | J10: =SUMIFS(Banco[Monto],Banco[CtaCtbl],$C10,Banco[Periodo Contable],TEXT(J$3,"mmm-yyyy")) -> 0 | K10: =SUMIFS(Banco[Monto],Banco[CtaCtbl],$C10,Banco[Periodo Contable],TEXT(K$3,"mmm-yyyy")) -> 0 | L10: =SUMIFS(Banco[Monto],Banco[CtaCtbl],$C10,Banco[Periodo Contable],TEXT(L$3,"mmm-yyyy")) -> 0 | M10: =SUMIFS(Banco[Monto],Banco[CtaCtbl],$C10,Banco[Periodo Contable],TEXT(M$3,"mmm-yyyy")) -> 0 | N10: =SUMIFS(Banco[Monto],Banco[CtaCtbl],$C10,Banco[Periodo Contable],TEXT(N$3,"mmm-yyyy")) -> 0 | O10: =SUMIFS(Banco[Monto],Banco[CtaCtbl],$C10,Banco[Periodo Contable],TEXT(O$3,"mmm-yyyy")) -> 0 | P10: =SUMIFS(Banco[Monto],Banco[CtaCtbl],$C10,Banco[Periodo Contable],TEXT(P$3,"mmm-yyyy")) -> 0 | Q10: =SUMIFS(Banco[Monto],Banco[CtaCtbl],$C10,Banco[Periodo Contable],TEXT(Q$3,"mmm-yyyy")) -> 0 | ... U10: =SUMIFS(Banco[Monto],Banco[CtaCtbl],$C10,Banco[Periodo Contable],TEXT(U$3,"mmm-yyyy")) -> 0 | V10: =SUM(Tabla17[[#This Row],[ene-22]:[dic-22]]) -> 0 | W10: =SUMIFS(Banco[Monto],Banco[CtaCtbl],$C10,Banco[Periodo Contable],TEXT(W$3,"mmm-yyyy")) -> 0 | X10: =SUMIFS(Banco[Monto],Banco[CtaCtbl],$C10,Banco[Periodo Contable],TEXT(X$3,"mmm-yyyy")) -> 0 | Y10: =SUMIFS(Banco[Monto],Banco[CtaCtbl],$C10,Banco[Periodo Contable],TEXT(Y$3,"mmm-yyyy")) -> 0 | Z10: =SUMIFS(Banco[Monto],Banco[CtaCtbl],$C10,Banco[Periodo Contable],TEXT(Z$3,"mmm-yyyy")) -> 0 | AA10: =SUMIFS(Banco[Monto],Banco[CtaCtbl],$C10,Banco[Periodo Contable],TEXT(AA$3,"mmm-yyyy")) -> 0 | AB10: =SUMIFS(Banco[Monto],Banco[CtaCtbl],$C10,Banco[Periodo Contable],TEXT(AB$3,"mmm-yyyy")) -> 0 | AC10: =SUMIFS(Banco[Monto],Banco[CtaCtbl],$C10,Banco[Periodo Contable],TEXT(AC$3,"mmm-yyyy")) -> 0 | AD10: =SUMIFS(Banco[Monto],Banco[CtaCtbl],$C10,Banco[Periodo Contable],TEXT(AD$3,"mmm-yyyy")) -> 0 | ... AH10: =SUMIFS(Banco[Monto],Banco[CtaCtbl],$C10,Banco[Periodo Contable],TEXT(AH$3,"mmm-yyyy")) -> 0 | AI10: =SUM(Tabla17[[#This Row],[ene-23]:[dic-23]]) -> 0 | AJ10: =SUMIFS(Banco[Monto],Banco[CtaCtbl],$C10,Banco[Periodo Contable],TEXT(AJ$3,"mmm-yyyy")) -> 0 | AK10: =SUMIFS(Banco[Monto],Banco[CtaCtbl],$C10,Banco[Periodo Contable],TEXT(AK$3,"mmm-yyyy")) -> 0 | AL10: =SUMIFS(Banco[Monto],Banco[CtaCtbl],$C10,Banco[Periodo Contable],TEXT(AL$3,"mmm-yyyy")) -> 0 | AM10: =SUMIFS(Banco[Monto],Banco[CtaCtbl],$C10,Banco[Periodo Contable],TEXT(AM$3,"mmm-yyyy")) -> 0 | AN10: =SUMIFS(Banco[Monto],Banco[CtaCtbl],$C10,Banco[Periodo Contable],TEXT(AN$3,"mmm-yyyy")) -> 0 | AO10: =SUMIFS(Banco[Monto],Banco[CtaCtbl],$C10,Banco[Periodo Contable],TEXT(AO$3,"mmm-yyyy")) -> 0 | AP10: =SUMIFS(Banco[Monto],Banco[CtaCtbl],$C10,Banco[Periodo Contable],TEXT(AP$3,"mmm-yyyy")) -> 0 | AQ10: =SUMIFS(Banco[Monto],Banco[CtaCtbl],$C10,Banco[Periodo Contable],TEXT(AQ$3,"mmm-yyyy")) -> 0 | ... AU10: =SUMIFS(Banco[Monto],Banco[CtaCtbl],$C10,Banco[Periodo Contable],TEXT(AU$3,"mmm-yyyy")) -> 0 | AV10: =SUM(Tabla17[[#This Row],[ene-24]:[dic-24]]) -> 0 | AW10: =SUMIFS(Banco[Monto],Banco[CtaCtbl],$C10,Banco[Periodo Contable],TEXT(AW$3,"mmm-yyyy")) -> 0 | AX10: =SUMIFS(Banco[Monto],Banco[CtaCtbl],$C10,Banco[Periodo Contable],TEXT(AX$3,"mmm-yyyy")) -> 0 | AY10: =SUMIFS(Banco[Monto],Banco[CtaCtbl],$C10,Banco[Periodo Contable],TEXT(AY$3,"mmm-yyyy")) -> 0 | AZ10: =SUMIFS(Banco[Monto],Banco[CtaCtbl],$C10,Banco[Periodo Contable],TEXT(AZ$3,"mmm-yyyy")) -> 0 | BA10: =SUMIFS(Banco[Monto],Banco[CtaCtbl],$C10,Banco[Periodo Contable],TEXT(BA$3,"mmm-yyyy")) -> 0 | BB10: =SUMIFS(Banco[Monto],Banco[CtaCtbl],$C10,Banco[Periodo Contable],TEXT(BB$3,"mmm-yyyy")) -> 0 | BC10: =SUMIFS(Banco[Monto],Banco[CtaCtbl],$C10,Banco[Periodo Contable],TEXT(BC$3,"mmm-yyyy")) -> 0 | BD10: =SUMIFS(Banco[Monto],Banco[CtaCtbl],$C10,Banco[Periodo Contable],TEXT(BD$3,"mmm-yyyy")) -> 0 | ... BH10: =SUMIFS(Banco[Monto],Banco[CtaCtbl],$C10,Banco[Periodo Contable],TEXT(BH$3,"mmm-yyyy")) -> 0 | BI10: =SUM(Tabla17[[#This Row],[ene-25]:[dic-25]]) -> 0 | BJ10: =SUMIFS(Banco[Monto],Banco[CtaCtbl],$C10,Banco[Periodo Contable],TEXT(BJ$3,"mmm-yyyy")) -> 0 | BK10: =SUMIFS(Banco[Monto],Banco[CtaCtbl],$C10,Banco[Periodo Contable],TEXT(BK$3,"mmm-yyyy")) -> 0 | BL10: =SUMIFS(Banco[Monto],Banco[CtaCtbl],$C10,Banco[Periodo Contable],TEXT(BL$3,"mmm-yyyy")) -> 0 | BM10: =SUMIFS(Banco[Monto],Banco[CtaCtbl],$C10,Banco[Periodo Contable],TEXT(BM$3,"mmm-yyyy")) -> 0 | BN10: =SUMIFS(Banco[Monto],Banco[CtaCtbl],$C10,Banco[Periodo Contable],TEXT(BN$3,"mmm-yyyy")) -> 0 | BO10: =SUMIFS(Banco[Monto],Banco[CtaCtbl],$C10,Banco[Periodo Contable],TEXT(BO$3,"mmm-yyyy")) -> 0 | BP10: =SUMIFS(Banco[Monto],Banco[CtaCtbl],$C10,Banco[Periodo Contable],TEXT(BP$3,"mmm-yyyy")) -> 0 | BQ10: =SUMIFS(Banco[Monto],Banco[CtaCtbl],$C10,Banco[Periodo Contable],TEXT(BQ$3,"mmm-yyyy")) -> 0 | ... BU10: =SUMIFS(Banco[Monto],Banco[CtaCtbl],$C10,Banco[Periodo Contable],TEXT(BU$3,"mmm-yyyy")) -> 0 | BV10: =SUM(Tabla17[[#This Row],[ene-26]:[dic-26]]) -> 0 | BW10: =SUMIFS(Banco[Monto],Banco[CtaCtbl],$C10,Banco[Periodo Contable],TEXT(BW$3,"mmm-yyyy")) -> 0
A11: 1.02.02 | B11: Otras Multas | C11: =+Tabla17[[#This Row],[Cuenta]]&" - "&Tabla17[[#This Row],[Descripcion Cuenta]] -> 1.02.02 - Otras Multas | E11: =SUMIFS(Banco[Monto],Banco[CtaCtbl],$C11,Banco[Periodo Contable],TEXT(E$3,"mmm-yyyy")) -> 0 | F11: =SUMIFS(Banco[Monto],Banco[CtaCtbl],$C11,Banco[Periodo Contable],TEXT(F$3,"mmm-yyyy")) -> 0 | G11: =SUMIFS(Banco[Monto],Banco[CtaCtbl],$C11,Banco[Periodo Contable],TEXT(G$3,"mmm-yyyy")) -> 0 | H11: =SUMIFS(Banco[Monto],Banco[CtaCtbl],$C11,Banco[Periodo Contable],TEXT(H$3,"mmm-yyyy")) -> 0 | I11: =SUM(Tabla17[[#This Row],[sept-21]:[dic-21]]) -> 0 | J11: =SUMIFS(Banco[Monto],Banco[CtaCtbl],$C11,Banco[Periodo Contable],TEXT(J$3,"mmm-yyyy")) -> 0 | K11: =SUMIFS(Banco[Monto],Banco[CtaCtbl],$C11,Banco[Periodo Contable],TEXT(K$3,"mmm-yyyy")) -> 0 | L11: =SUMIFS(Banco[Monto],Banco[CtaCtbl],$C11,Banco[Periodo Contable],TEXT(L$3,"mmm-yyyy")) -> 0 | M11: =SUMIFS(Banco[Monto],Banco[CtaCtbl],$C11,Banco[Periodo Contable],TEXT(M$3,"mmm-yyyy")) -> 0 | N11: =SUMIFS(Banco[Monto],Banco[CtaCtbl],$C11,Banco[Periodo Contable],TEXT(N$3,"mmm-yyyy")) -> 0 | O11: =SUMIFS(Banco[Monto],Banco[CtaCtbl],$C11,Banco[Periodo Contable],TEXT(O$3,"mmm-yyyy")) -> 0 | P11: =SUMIFS(Banco[Monto],Banco[CtaCtbl],$C11,Banco[Periodo Contable],TEXT(P$3,"mmm-yyyy")) -> 0 | Q11: =SUMIFS(Banco[Monto],Banco[CtaCtbl],$C11,Banco[Periodo Contable],TEXT(Q$3,"mmm-yyyy")) -> 0 | ... U11: =SUMIFS(Banco[Monto],Banco[CtaCtbl],$C11,Banco[Periodo Contable],TEXT(U$3,"mmm-yyyy")) -> 0 | V11: =SUM(Tabla17[[#This Row],[ene-22]:[dic-22]]) -> 0 | W11: =SUMIFS(Banco[Monto],Banco[CtaCtbl],$C11,Banco[Periodo Contable],TEXT(W$3,"mmm-yyyy")) -> 0 | X11: =SUMIFS(Banco[Monto],Banco[CtaCtbl],$C11,Banco[Periodo Contable],TEXT(X$3,"mmm-yyyy")) -> 0 | Y11: =SUMIFS(Banco[Monto],Banco[CtaCtbl],$C11,Banco[Periodo Contable],TEXT(Y$3,"mmm-yyyy")) -> 0 | Z11: =SUMIFS(Banco[Monto],Banco[CtaCtbl],$C11,Banco[Periodo Contable],TEXT(Z$3,"mmm-yyyy")) -> 0 | AA11: =SUMIFS(Banco[Monto],Banco[CtaCtbl],$C11,Banco[Periodo Contable],TEXT(AA$3,"mmm-yyyy")) -> 0 | AB11: =SUMIFS(Banco[Monto],Banco[CtaCtbl],$C11,Banco[Periodo Contable],TEXT(AB$3,"mmm-yyyy")) -> 0 | AC11: =SUMIFS(Banco[Monto],Banco[CtaCtbl],$C11,Banco[Periodo Contable],TEXT(AC$3,"mmm-yyyy")) -> 0 | AD11: =SUMIFS(Banco[Monto],Banco[CtaCtbl],$C11,Banco[Periodo Contable],TEXT(AD$3,"mmm-yyyy")) -> 0 | ... AH11: =SUMIFS(Banco[Monto],Banco[CtaCtbl],$C11,Banco[Periodo Contable],TEXT(AH$3,"mmm-yyyy")) -> 0 | AI11: =SUM(Tabla17[[#This Row],[ene-23]:[dic-23]]) -> 0 | AJ11: =SUMIFS(Banco[Monto],Banco[CtaCtbl],$C11,Banco[Periodo Contable],TEXT(AJ$3,"mmm-yyyy")) -> 0 | AK11: =SUMIFS(Banco[Monto],Banco[CtaCtbl],$C11,Banco[Periodo Contable],TEXT(AK$3,"mmm-yyyy")) -> 0 | AL11: =SUMIFS(Banco[Monto],Banco[CtaCtbl],$C11,Banco[Periodo Contable],TEXT(AL$3,"mmm-yyyy")) -> 0 | AM11: =SUMIFS(Banco[Monto],Banco[CtaCtbl],$C11,Banco[Periodo Contable],TEXT(AM$3,"mmm-yyyy")) -> 0 | AN11: =SUMIFS(Banco[Monto],Banco[CtaCtbl],$C11,Banco[Periodo Contable],TEXT(AN$3,"mmm-yyyy")) -> 0 | AO11: =SUMIFS(Banco[Monto],Banco[CtaCtbl],$C11,Banco[Periodo Contable],TEXT(AO$3,"mmm-yyyy")) -> 0 | AP11: =SUMIFS(Banco[Monto],Banco[CtaCtbl],$C11,Banco[Periodo Contable],TEXT(AP$3,"mmm-yyyy")) -> 0 | AQ11: =SUMIFS(Banco[Monto],Banco[CtaCtbl],$C11,Banco[Periodo Contable],TEXT(AQ$3,"mmm-yyyy")) -> 0 | ... AU11: =SUMIFS(Banco[Monto],Banco[CtaCtbl],$C11,Banco[Periodo Contable],TEXT(AU$3,"mmm-yyyy")) -> 0 | AV11: =SUM(Tabla17[[#This Row],[ene-24]:[dic-24]]) -> 0 | AW11: =SUMIFS(Banco[Monto],Banco[CtaCtbl],$C11,Banco[Periodo Contable],TEXT(AW$3,"mmm-yyyy")) -> 0 | AX11: =SUMIFS(Banco[Monto],Banco[CtaCtbl],$C11,Banco[Periodo Contable],TEXT(AX$3,"mmm-yyyy")) -> 0 | AY11: =SUMIFS(Banco[Monto],Banco[CtaCtbl],$C11,Banco[Periodo Contable],TEXT(AY$3,"mmm-yyyy")) -> 0 | AZ11: =SUMIFS(Banco[Monto],Banco[CtaCtbl],$C11,Banco[Periodo Contable],TEXT(AZ$3,"mmm-yyyy")) -> 0 | BA11: =SUMIFS(Banco[Monto],Banco[CtaCtbl],$C11,Banco[Periodo Contable],TEXT(BA$3,"mmm-yyyy")) -> 0 | BB11: =SUMIFS(Banco[Monto],Banco[CtaCtbl],$C11,Banco[Periodo Contable],TEXT(BB$3,"mmm-yyyy")) -> 0 | BC11: =SUMIFS(Banco[Monto],Banco[CtaCtbl],$C11,Banco[Periodo Contable],TEXT(BC$3,"mmm-yyyy")) -> 0 | BD11: =SUMIFS(Banco[Monto],Banco[CtaCtbl],$C11,Banco[Periodo Contable],TEXT(BD$3,"mmm-yyyy")) -> 0 | ... BH11: =SUMIFS(Banco[Monto],Banco[CtaCtbl],$C11,Banco[Periodo Contable],TEXT(BH$3,"mmm-yyyy")) -> 0 | BI11: =SUM(Tabla17[[#This Row],[ene-25]:[dic-25]]) -> 0 | BJ11: =SUMIFS(Banco[Monto],Banco[CtaCtbl],$C11,Banco[Periodo Contable],TEXT(BJ$3,"mmm-yyyy")) -> 0 | BK11: =SUMIFS(Banco[Monto],Banco[CtaCtbl],$C11,Banco[Periodo Contable],TEXT(BK$3,"mmm-yyyy")) -> 0 | BL11: =SUMIFS(Banco[Monto],Banco[CtaCtbl],$C11,Banco[Periodo Contable],TEXT(BL$3,"mmm-yyyy")) -> 0 | BM11: =SUMIFS(Banco[Monto],Banco[CtaCtbl],$C11,Banco[Periodo Contable],TEXT(BM$3,"mmm-yyyy")) -> 0 | BN11: =SUMIFS(Banco[Monto],Banco[CtaCtbl],$C11,Banco[Periodo Contable],TEXT(BN$3,"mmm-yyyy")) -> 0 | BO11: =SUMIFS(Banco[Monto],Banco[CtaCtbl],$C11,Banco[Periodo Contable],TEXT(BO$3,"mmm-yyyy")) -> 0 | BP11: =SUMIFS(Banco[Monto],Banco[CtaCtbl],$C11,Banco[Periodo Contable],TEXT(BP$3,"mmm-yyyy")) -> 0 | BQ11: =SUMIFS(Banco[Monto],Banco[CtaCtbl],$C11,Banco[Periodo Contable],TEXT(BQ$3,"mmm-yyyy")) -> 0 | ... BU11: =SUMIFS(Banco[Monto],Banco[CtaCtbl],$C11,Banco[Periodo Contable],TEXT(BU$3,"mmm-yyyy")) -> 0 | BV11: =SUM(Tabla17[[#This Row],[ene-26]:[dic-26]]) -> 0 | BW11: =SUMIFS(Banco[Monto],Banco[CtaCtbl],$C11,Banco[Periodo Contable],TEXT(BW$3,"mmm-yyyy")) -> 0
A12: 1.03 | B12: Aportes Adicionales | C12: =+Tabla17[[#This Row],[Cuenta]]&" - "&Tabla17[[#This Row],[Descripcion Cuenta]] -> 1.03 - Aportes Adicionales | E12: =SUBTOTAL(9,E13:E16) -> 0 | F12: =SUBTOTAL(9,F13:F16) -> 0 | G12: =SUBTOTAL(9,G13:G16) -> 0 | H12: =SUBTOTAL(9,H13:H16) -> 0 | I12: =SUM(Tabla17[[#This Row],[sept-21]:[dic-21]]) -> 0 | J12: =SUBTOTAL(9,J13:J16) -> 0 | K12: =SUBTOTAL(9,K13:K16) -> 0 | L12: =SUBTOTAL(9,L13:L16) -> 0 | M12: =SUBTOTAL(9,M13:M16) -> 0 | N12: =SUBTOTAL(9,N13:N16) -> 107000000 | O12: =SUBTOTAL(9,O13:O16) -> 3000000 | P12: =SUBTOTAL(9,P13:P16) -> 0 | Q12: =SUBTOTAL(9,Q13:Q16) -> 0 | ... BW12: =SUBTOTAL(9,BW13:BW16) -> 0
